Workbook
Name _09_09_16_0_05: #REF!
Name _09_09_16_0_05: 'FIG.4. INSU (DATA)'!$A$255
Name a_1: #REF!
Name a_1: #REF!
Name a_2: #REF!
Name a_2: #REF!
Name a_3: #REF!
Name a_3: #REF!
Name a_4: #REF!
Name a_4: #REF!
Name a_5: #REF!
Name a_5: #REF!
Name h: #REF!
Name h: #REF!
Name inc: #REF!
Name inc: #REF!
Name Ta: #REF!
Name Ta: #REF!
Name X: #REF!

Sheet FIG.4. INSU (DATA)
A1: DATE | C1: OUTDOOR | D1: CONTROL CELL | E1: WATER | F1: INDOOR
A2: 08/31/16 03:00:00 AM | B2: 0.125 | C2: 20.007 | D2: 22.058 | E2: 19.41 | F2: 21.336
A3: 08/31/16 03:05:00 AM | C3: 19.984 | D3: 22.011 | E3: 19.393 | F3: 21.37
A4: 08/31/16 03:10:00 AM | C4: 19.96 | D4: 21.987 | E4: 19.383 | F4: 21.328
A5: 08/31/16 03:15:00 AM | C5: 19.888 | D5: 21.939 | E5: 19.369 | F5: 21.264
A6: 08/31/16 03:20:00 AM | C6: 19.841 | D6: 21.867 | E6: 19.358 | F6: 21.264
A7: 08/31/16 03:25:00 AM | C7: 19.817 | D7: 21.843 | E7: 19.344 | F7: 21.239
A8: 08/31/16 03:30:00 AM | C8: 19.793 | D8: 21.772 | E8: 19.335 | F8: 21.221
A9: 08/31/16 03:35:00 AM | C9: 19.77 | D9: 21.748 | E9: 19.319 | F9: 21.252
A10: 08/31/16 03:40:00 AM | C10: 19.722 | D10: 21.7 | E10: 19.31 | F10: 21.172
A11: 08/31/16 03:45:00 AM | C11: 19.651 | D11: 21.652 | E11: 19.303 | F11: 21.12
A12: 08/31/16 03:50:00 AM | C12: 19.603 | D12: 21.604 | E12: 19.286 | F12: 21.091
A13: 08/31/16 03:55:00 AM | C13: 19.603 | D13: 21.557 | E13: 19.276 | F13: 21.082
A14: 08/31/16 04:00:00 AM | C14: 19.579 | D14: 21.509 | E14: 19.264 | F14: 21.023
... A25: 08/31/16 04:55:00 AM | C25: 19.056 | D25: 21.032 | E25: 19.132 | F25: 20.6
A26: 08/31/16 05:00:00 AM | B26: 0.20833333 | C26: 19.032 | D26: 20.984 | E26: 19.114 | F26: 20.589
A27: 08/31/16 05:05:00 AM | C27: 19.032 | D27: 20.96 | E27: 19.099 | F27: 20.604
A28: 08/31/16 05:10:00 AM | C28: 19.032 | D28: 20.936 | E28: 19.089 | F28: 20.537
A29: 08/31/16 05:15:00 AM | C29: 19.008 | D29: 20.913 | E29: 19.074 | F29: 20.565
A30: 08/31/16 05:20:00 AM | C30: 18.961 | D30: 20.865 | E30: 19.062 | F30: 20.496
A31: 08/31/16 05:25:00 AM | C31: 18.889 | D31: 20.817 | E31: 19.05 | F31: 20.443
A32: 08/31/16 05:30:00 AM | C32: 18.818 | D32: 20.77 | E32: 19.036 | F32: 20.399
A33: 08/31/16 05:35:00 AM | C33: 18.771 | D33: 20.746 | E33: 19.02 | F33: 20.399
A34: 08/31/16 05:40:00 AM | C34: 18.747 | D34: 20.698 | E34: 19.005 | F34: 20.344
A35: 08/31/16 05:45:00 AM | C35: 18.771 | D35: 20.674 | E35: 18.996 | F35: 20.365
A36: 08/31/16 05:50:00 AM | C36: 18.794 | D36: 20.65 | E36: 18.982 | F36: 20.376
A37: 08/31/16 05:55:00 AM | C37: 18.747 | D37: 20.627 | E37: 18.968 | F37: 20.271
A38: 08/31/16 06:00:00 AM | C38: 18.699 | D38: 20.579 | E38: 18.956 | F38: 20.232
... A49: 08/31/16 06:55:00 AM | C49: 18.39 | D49: 20.889 | E49: 18.845 | F49: 20.914
A50: 08/31/16 07:00:00 AM | B50: 0.29166667 | C50: 18.414 | D50: 20.936 | E50: 18.84 | F50: 20.942
A51: 08/31/16 07:05:00 AM | C51: 18.461 | D51: 20.96 | E51: 18.837 | F51: 20.971
A52: 08/31/16 07:10:00 AM | C52: 18.58 | D52: 21.008 | E52: 18.834 | F52: 20.996
A53: 08/31/16 07:15:00 AM | C53: 18.675 | D53: 21.032 | E53: 18.828 | F53: 21.027
A54: 08/31/16 07:20:00 AM | C54: 18.794 | D54: 21.079 | E54: 18.825 | F54: 21.06
A55: 08/31/16 07:25:00 AM | C55: 18.985 | D55: 21.103 | E55: 18.822 | F55: 21.087
A56: 08/31/16 07:30:00 AM | C56: 19.127 | D56: 21.127 | E56: 18.822 | F56: 21.112
A57: 08/31/16 07:35:00 AM | C57: 19.508 | D57: 21.175 | E57: 18.82 | F57: 21.141
A58: 08/31/16 07:40:00 AM | C58: 19.674 | D58: 21.223 | E58: 18.821 | F58: 21.172
A59: 08/31/16 07:45:00 AM | C59: 19.865 | D59: 21.246 | E59: 18.822 | F59: 21.205
A60: 08/31/16 07:50:00 AM | C60: 20.079 | D60: 21.294 | E60: 18.824 | F60: 21.24
...

Sheet FIG.5. INSU+WAHE (DATA)
A1: DATE | C1: WATER | D1: OUTDOOR | E1: CONTROL CELL | F1: INDOOR | G1: POND OUTLET
A2: 08/22/16 03:00:00 AM | B2: 0.125 | C2: 20.138 | D2: 17.011 | E2: 19.888 | F2: 20.774 | G2: 20.491
A3: 08/22/16 03:05:00 AM | C3: 20.138 | D3: 17.296 | E3: 19.841 | F3: 20.714 | G3: 20.43
A4: 08/22/16 03:10:00 AM | C4: 20.043 | D4: 17.368 | E4: 19.793 | F4: 20.667 | G4: 20.375
A5: 08/22/16 03:15:00 AM | C5: 20.043 | D5: 17.391 | E5: 19.793 | F5: 20.619 | G5: 20.321
A6: 08/22/16 03:20:00 AM | C6: 19.948 | D6: 17.272 | E6: 19.77 | F6: 20.574 | G6: 20.273
A7: 08/22/16 03:25:00 AM | C7: 19.948 | D7: 17.32 | E7: 19.746 | F7: 20.532 | G7: 20.224
A8: 08/22/16 03:30:00 AM | C8: 19.853 | D8: 17.177 | E8: 19.722 | F8: 20.486 | G8: 20.176
A9: 08/22/16 03:35:00 AM | C9: 19.853 | D9: 16.963 | E9: 19.698 | F9: 20.439 | G9: 20.123
A10: 08/22/16 03:40:00 AM | C10: 19.758 | D10: 16.939 | E10: 19.651 | F10: 20.385 | G10: 20.076
A11: 08/22/16 03:45:00 AM | C11: 19.758 | D11: 16.844 | E11: 19.603 | F11: 20.338 | G11: 20.03
A12: 08/22/16 03:50:00 AM | C12: 19.662 | D12: 16.844 | E12: 19.555 | F12: 20.288 | G12: 19.986
A13: 08/22/16 03:55:00 AM | C13: 19.662 | D13: 16.749 | E13: 19.508 | F13: 20.237 | G13: 19.933
A14: 08/22/16 04:00:00 AM | C14: 19.567 | D14: 16.63 | E14: 19.484 | F14: 20.199 | G14: 19.889
... A25: 08/22/16 04:55:00 AM | C25: 19.187 | D25: 16.415 | E25: 19.032 | F25: 19.703 | G25: 19.4
A26: 08/22/16 05:00:00 AM | B26: 0.20833333 | C26: 19.092 | D26: 16.487 | E26: 18.985 | F26: 19.661 | G26: 19.359
A27: 08/22/16 05:05:00 AM | C27: 19.092 | D27: 16.487 | E27: 18.961 | F27: 19.612 | G27: 19.315
A28: 08/22/16 05:10:00 AM | C28: 18.996 | D28: 16.511 | E28: 18.937 | F28: 19.57 | G28: 19.274
A29: 08/22/16 05:15:00 AM | C29: 18.996 | D29: 16.32 | E29: 18.889 | F29: 19.53 | G29: 19.231
A30: 08/22/16 05:20:00 AM | C30: 18.901 | D30: 16.177 | E30: 18.842 | F30: 19.49 | G30: 19.189
A31: 08/22/16 05:25:00 AM | C31: 18.901 | D31: 16.106 | E31: 18.794 | F31: 19.445 | G31: 19.15
A32: 08/22/16 05:30:00 AM | C32: 18.806 | D32: 16.201 | E32: 18.771 | F32: 19.402 | G32: 19.109
A33: 08/22/16 05:35:00 AM | C33: 18.806 | D33: 16.296 | E33: 18.747 | F33: 19.354 | G33: 19.065
A34: 08/22/16 05:40:00 AM | C34: 18.806 | D34: 16.296 | E34: 18.699 | F34: 19.314 | G34: 19.021
A35: 08/22/16 05:45:00 AM | C35: 18.711 | D35: 16.272 | E35: 18.675 | F35: 19.273 | G35: 18.981
A36: 08/22/16 05:50:00 AM | C36: 18.711 | D36: 16.415 | E36: 18.652 | F36: 19.229 | G36: 18.946
A37: 08/22/16 05:55:00 AM | C37: 18.711 | D37: 16.32 | E37: 18.604 | F37: 19.19 | G37: 18.908
A38: 08/22/16 06:00:00 AM | C38: 18.616 | D38: 16.177 | E38: 18.604 | F38: 19.148 | G38: 18.869
... A49: 08/22/16 06:55:00 AM | C49: 18.331 | D49: 16.725 | E49: 18.343 | F49: 18.762 | G49: 18.496
A50: 08/22/16 07:00:00 AM | B50: 0.29166667 | C50: 18.331 | D50: 17.034 | E50: 18.366 | F50: 18.742 | G50: 18.472
A51: 08/22/16 07:05:00 AM | C51: 18.236 | D51: 17.13 | E51: 18.39 | F51: 18.715 | G51: 18.442
A52: 08/22/16 07:10:00 AM | C52: 18.236 | D52: 17.32 | E52: 18.414 | F52: 18.698 | G52: 18.417
A53: 08/22/16 07:15:00 AM | C53: 18.236 | D53: 17.605 | E53: 18.461 | F53: 18.685 | G53: 18.402
A54: 08/22/16 07:20:00 AM | C54: 18.236 | D54: 17.962 | E54: 18.509 | F54: 18.673 | G54: 18.378
A55: 08/22/16 07:25:00 AM | C55: 18.236 | D55: 18.438 | E55: 18.58 | F55: 18.664 | G55: 18.372
A56: 08/22/16 07:30:00 AM | C56: 18.236 | D56: 18.985 | E56: 18.675 | F56: 18.664 | G56: 18.364
A57: 08/22/16 07:35:00 AM | C57: 18.236 | D57: 19.746 | E57: 18.747 | F57: 18.667 | G57: 18.356
A58: 08/22/16 07:40:00 AM | C58: 18.236 | D58: 20.77 | E58: 18.842 | F58: 18.67 | G58: 18.356
A59: 08/22/16 07:45:00 AM | C59: 18.236 | D59: 21.509 | E59: 18.913 | F59: 18.684 | G59: 18.356
A60: 08/22/16 07:50:00 AM | C60: 18.236 | D60: 21.437 | E60: 18.961 | F60: 18.694 | G60: 18.355
...

Sheet FIG.6. ALUM (DATA)
A1: DATE | C1: INDOOR | D1: WATER | E1: ALUM. INSIDE | F1: OUTDOOR | G1: CONTROL CELL
A2: 07/27/16 03:00:00 AM | B2: 0.125 | C2: 25.939 | D2: 26.83505 | E2: 21.011 | F2: 21.223 | G2: 23.20825
A3: 07/27/16 03:05:00 AM | C3: 25.939 | D3: 26.83505 | E3: 20.889 | F3: 21.199 | G3: 23.18509
A4: 07/27/16 03:10:00 AM | C4: 25.89 | D4: 26.73999 | E4: 20.823 | F4: 21.079 | G4: 23.13877
A5: 07/27/16 03:15:00 AM | C5: 25.841 | D5: 26.73999 | E5: 20.902 | F5: 21.032 | G5: 23.09245
A6: 07/27/16 03:20:00 AM | C6: 25.793 | D6: 26.73999 | E6: 20.842 | F6: 21.056 | G6: 23.045165
A7: 07/27/16 03:25:00 AM | C7: 25.768 | D7: 26.73999 | E7: 20.838 | F7: 21.151 | G7: 23.022005
A8: 07/27/16 03:30:00 AM | C8: 25.72 | D8: 26.64396 | E8: 20.764 | F8: 21.103 | G8: 22.975685
A9: 07/27/16 03:35:00 AM | C9: 25.695 | D9: 26.64396 | E9: 20.753 | F9: 21.127 | G9: 22.952525
A10: 07/27/16 03:40:00 AM | C10: 25.647 | D10: 26.64396 | E10: 20.673 | F10: 21.056 | G10: 22.906205
A11: 07/27/16 03:45:00 AM | C11: 25.598 | D11: 26.64396 | E11: 20.6 | F11: 20.936 | G11: 22.859885
A12: 07/27/16 03:50:00 AM | C12: 25.574 | D12: 26.64396 | E12: 20.662 | F12: 20.984 | G12: 22.813565
A13: 07/27/16 03:55:00 AM | C13: 25.501 | D13: 26.5489 | E13: 20.54 | F13: 20.889 | G13: 22.790405
A14: 07/27/16 04:00:00 AM | C14: 25.501 | D14: 26.5489 | E14: 20.548 | F14: 20.77 | G14: 22.744085
... A25: 07/27/16 04:55:00 AM | C25: 25.113 | D25: 26.35781 | E25: 20.652 | F25: 20.77 | G25: 22.37256
A26: 07/27/16 05:00:00 AM | B26: 0.20833333 | C26: 25.065 | D26: 26.35781 | E26: 20.601 | F26: 20.603 | G26: 22.32624
A27: 07/27/16 05:05:00 AM | C27: 25.04 | D27: 26.26275 | E27: 20.643 | F27: 20.388 | G27: 22.30308
A28: 07/27/16 05:10:00 AM | C28: 25.016 | D28: 26.26275 | E28: 20.814 | F28: 20.412 | G28: 22.25676
A29: 07/27/16 05:15:00 AM | C29: 24.968 | D29: 26.26275 | E29: 20.88 | F29: 20.579 | G29: 22.2336
A30: 07/27/16 05:20:00 AM | C30: 24.968 | D30: 26.26275 | E30: 20.971 | F30: 20.936 | G30: 22.21044
A31: 07/27/16 05:25:00 AM | C31: 24.944 | D31: 26.26275 | E31: 21.012 | F31: 20.889 | G31: 22.18728
A32: 07/27/16 05:30:00 AM | C32: 24.895 | D32: 26.26275 | E32: 20.936 | F32: 20.793 | G32: 22.16412
A33: 07/27/16 05:35:00 AM | C33: 24.871 | D33: 26.16769 | E33: 20.79 | F33: 20.793 | G33: 22.16412
A34: 07/27/16 05:40:00 AM | C34: 24.847 | D34: 26.16769 | E34: 20.632 | F34: 20.984 | G34: 22.14096
A35: 07/27/16 05:45:00 AM | C35: 24.798 | D35: 26.16769 | E35: 20.464 | F35: 20.984 | G35: 22.1178
A36: 07/27/16 05:50:00 AM | C36: 24.774 | D36: 26.16769 | E36: 20.405 | F36: 21.008 | G36: 22.1178
A37: 07/27/16 05:55:00 AM | C37: 24.726 | D37: 26.16769 | E37: 20.237 | F37: 20.793 | G37: 22.07148
A38: 07/27/16 06:00:00 AM | C38: 24.702 | D38: 26.07263 | E38: 20.201 | F38: 20.65 | G38: 22.04832
... A49: 07/27/16 06:55:00 AM | C49: 24.532 | D49: 25.88251 | E49: 21.194 | F49: 22.178 | G49: 21.933485
A50: 07/27/16 07:00:00 AM | B50: 0.29166667 | C50: 24.581 | D50: 25.88251 | E50: 21.4 | F50: 22.465 | G50: 21.97884
A51: 07/27/16 07:05:00 AM | C51: 24.581 | D51: 25.88251 | E51: 21.458 | F51: 22.609 | G51: 22.02516
A52: 07/27/16 07:10:00 AM | C52: 24.629 | D52: 25.88251 | E52: 21.592 | F52: 22.776 | G52: 22.07148
A53: 07/27/16 07:15:00 AM | C53: 24.653 | D53: 25.78745 | E53: 21.84 | F53: 22.92 | G53: 22.1178
A54: 07/27/16 07:20:00 AM | C54: 24.677 | D54: 25.78745 | E54: 23.475 | F54: 23.136 | G54: 22.18728
A55: 07/27/16 07:25:00 AM | C55: 24.726 | D55: 25.78745 | E55: 24.077 | F55: 23.689 | G55: 22.2336
A56: 07/27/16 07:30:00 AM | C56: 24.75 | D56: 25.78745 | E56: 24.523 | F56: 24.098 | G56: 22.30308
A57: 07/27/16 07:35:00 AM | C57: 24.774 | D57: 25.78745 | E57: 24.928 | F57: 24.508 | G57: 22.3494
A58: 07/27/16 07:40:00 AM | C58: 24.823 | D58: 25.78745 | E58: 25.374 | F58: 24.774 | G58: 22.41888
A59: 07/27/16 07:45:00 AM | C59: 24.847 | D59: 25.78745 | E59: 25.778 | F59: 25.186 | G59: 22.51152
A60: 07/27/16 07:50:00 AM | C60: 24.871 | D60: 25.69336 | E60: 26.182 | F60: 25.331 | G60: 22.581
...

Sheet FIG.7. ALUM+WAHE (DATA)
A1: DATE | C1: INDOOR | D1: WATER | E1: ALUM. INSIDE | F1: POND OUTLET | G1: OUTDOOR | H1: CONTROL CELL
A2: 42651.125 | B2: 0.125 | C2: 23.593 | D2: 23.225 | E2: 16.12 | F2: 22.929 | G2: 17.082 | H2: 20.43623
A3: 42651.128 | C3: 23.569 | D3: 23.21 | E3: 16.086 | F3: 22.911 | G3: 16.939 | H3: 20.3631
A4: 42651.132 | C4: 23.545 | D4: 23.193 | E4: 15.953 | F4: 22.893 | G4: 16.868 | H4: 20.28894
A5: 42651.135 | C5: 23.521 | D5: 23.163 | E5: 15.877 | F5: 22.877 | G5: 16.868 | H5: 20.21581
A6: 42651.139 | C6: 23.497 | D6: 23.148 | E6: 15.863 | F6: 22.857 | G6: 16.63 | H6: 20.16637
A7: 42651.142 | C7: 23.448 | D7: 23.109 | E7: 15.752 | F7: 22.838 | G7: 16.558 | H7: 20.09324
A8: 42651.146 | C8: 23.424 | D8: 23.094 | E8: 15.676 | F8: 22.818 | G8: 16.439 | H8: 20.01908
A9: 42651.149 | C9: 23.424 | D9: 23.085 | E9: 15.582 | F9: 22.799 | G9: 16.272 | H9: 19.94595
A10: 42651.153 | C10: 23.4 | D10: 23.063 | E10: 15.572 | F10: 22.778 | G10: 16.106 | H10: 19.87282
A11: 42651.156 | C11: 23.376 | D11: 23.057 | E11: 15.53 | F11: 22.758 | G11: 16.034 | H11: 19.82338
A12: 42651.16 | C12: 23.352 | D12: 23.027 | E12: 15.418 | F12: 22.738 | G12: 15.939 | H12: 19.72553
A13: 42651.163 | C13: 23.328 | D13: 23.009 | E13: 15.4 | F13: 22.718 | G13: 16.129 | H13: 19.6524
A14: 42651.167 | C14: 23.304 | D14: 22.982 | E14: 15.412 | F14: 22.7 | G14: 16.058 | H14: 19.60296
... A25: 42651.205 | C25: 23.04 | D25: 22.803 | E25: 14.792 | F25: 22.505 | G25: 15.7 | H25: 19.01483
A26: 42651.208 | B26: 0.20833333 | C26: 23.016 | D26: 22.788 | E26: 14.768 | F26: 22.488 | G26: 15.652 | H26: 18.96642
A27: 42651.212 | C27: 22.992 | D27: 22.773 | E27: 14.728 | F27: 22.468 | G27: 15.629 | H27: 18.91698
A28: 42651.215 | C28: 22.968 | D28: 22.751 | E28: 14.707 | F28: 22.452 | G28: 15.748 | H28: 18.86857
A29: 42651.219 | C29: 22.944 | D29: 22.736 | E29: 14.782 | F29: 22.432 | G29: 15.581 | H29: 18.81913
A30: 42651.222 | C30: 22.92 | D30: 22.715 | E30: 14.738 | F30: 22.414 | G30: 15.533 | H30: 18.77072
A31: 42651.226 | C31: 22.896 | D31: 22.697 | E31: 14.646 | F31: 22.399 | G31: 15.7 | H31: 18.72128
A32: 42651.229 | C32: 22.872 | D32: 22.684 | E32: 14.655 | F32: 22.383 | G32: 15.748 | H32: 18.69656
A33: 42651.233 | C33: 22.848 | D33: 22.667 | E33: 14.65 | F33: 22.365 | G33: 15.509 | H33: 18.64815
A34: 42651.236 | C34: 22.848 | D34: 22.648 | E34: 14.586 | F34: 22.348 | G34: 15.39 | H34: 18.62343
A35: 42651.24 | C35: 22.824 | D35: 22.631 | E35: 14.71 | F35: 22.332 | G35: 15.342 | H35: 18.57399
A36: 42651.243 | C36: 22.8 | D36: 22.61 | E36: 14.604 | F36: 22.314 | G36: 15.461 | H36: 18.52558
A37: 42651.247 | C37: 22.776 | D37: 22.595 | E37: 14.55 | F37: 22.298 | G37: 15.342 | H37: 18.47614
A38: 42651.25 | C38: 22.753 | D38: 22.582 | E38: 14.438 | F38: 22.277 | G38: 15.27 | H38: 18.45245
... A49: 42651.288 | C49: 22.561 | D49: 22.381 | E49: 15.575 | F49: 22.12 | G49: 16.058 | H49: 18.18259
A50: 42651.292 | B50: 0.29166667 | C50: 22.561 | D50: 22.368 | E50: 15.743 | F50: 22.114 | G50: 16.32 | H50: 18.18259
A51: 42651.295 | C51: 22.561 | D51: 22.357 | E51: 16.099 | F51: 22.108 | G51: 16.677 | H51: 18.23203
A52: 42651.299 | C52: 22.537 | D52: 22.338 | E52: 16.442 | F52: 22.103 | G52: 16.987 | H52: 18.28044
A53: 42651.302 | C53: 22.537 | D53: 22.332 | E53: 16.738 | F53: 22.103 | G53: 17.344 | H53: 18.32988
A54: 42651.306 | C54: 22.537 | D54: 22.311 | E54: 17.66 | F54: 22.105 | G54: 17.701 | H54: 18.40301
A55: 42651.309 | C55: 22.537 | D55: 22.298 | E55: 18.488 | F55: 22.109 | G55: 18.247 | H55: 18.47614
A56: 42651.312 | C56: 22.537 | D56: 22.284 | E56: 18.687 | F56: 22.111 | G56: 18.319 | H56: 18.57399
A57: 42651.316 | C57: 22.537 | D57: 22.272 | E57: 18.787 | F57: 22.108 | G57: 18.2 | H57: 18.64815
A58: 42651.319 | C58: 22.537 | D58: 22.26 | E58: 18.727 | F58: 22.108 | G58: 18.343 | H58: 18.72128
A59: 42651.323 | C59: 22.537 | D59: 22.257 | E59: 19.401 | F59: 22.105 | G59: 18.438 | H59: 18.81913
A60: 42651.326 | C60: 22.537 | D60: 22.251 | E60: 19.933 | F60: 22.106 | G60: 18.557 | H60: 18.86857
...

Sheet FIG.9. ALUM+WAHE+SPRAY (DATA)
A1: DATE | C1: INDOOR | D1: WATER | E1: ALUM. INSIDE | F1: POND OUTLET | G1: OUTDOOR | H1: CONTROL CELL
A2: 08/15/16 03:00:00 AM | B2: 0.125 | C2: 27.801 | D2: 27.765 | E2: 26.642 | F2: 27.602 | G2: 20.817 | H2: 23.713
A3: 08/15/16 03:05:00 AM | C3: 27.776 | D3: 27.753 | E3: 26.532 | F3: 27.588 | G3: 20.746 | H3: 23.665
A4: 08/15/16 03:10:00 AM | C4: 27.751 | D4: 27.738 | E4: 26.642 | F4: 27.571 | G4: 20.698 | H4: 23.593
A5: 08/15/16 03:15:00 AM | C5: 27.727 | D5: 27.728 | E5: 26.656 | F5: 27.554 | G5: 20.579 | H5: 23.545
A6: 08/15/16 03:20:00 AM | C6: 27.702 | D6: 27.71 | E6: 26.648 | F6: 27.539 | G6: 20.603 | H6: 23.497
A7: 08/15/16 03:25:00 AM | C7: 27.702 | D7: 27.694 | E7: 26.356 | F7: 27.522 | G7: 20.436 | H7: 23.424
A8: 08/15/16 03:30:00 AM | C8: 27.677 | D8: 27.681 | E8: 26.564 | F8: 27.502 | G8: 20.341 | H8: 23.352
A9: 08/15/16 03:35:00 AM | C9: 27.653 | D9: 27.671 | E9: 26.454 | F9: 27.484 | G9: 20.198 | H9: 23.28
A10: 08/15/16 03:40:00 AM | C10: 27.653 | D10: 27.664 | E10: 26.359 | F10: 27.465 | G10: 20.246 | H10: 23.208
A11: 08/15/16 03:45:00 AM | C11: 27.628 | D11: 27.648 | E11: 26.515 | F11: 27.444 | G11: 20.365 | H11: 23.184
A12: 08/15/16 03:50:00 AM | C12: 27.604 | D12: 27.633 | E12: 26.396 | F12: 27.433 | G12: 20.198 | H12: 23.136
A13: 08/15/16 03:55:00 AM | C13: 27.579 | D13: 27.619 | E13: 26.469 | F13: 27.418 | G13: 20.341 | H13: 23.064
A14: 08/15/16 04:00:00 AM | C14: 27.554 | D14: 27.597 | E14: 26.459 | F14: 27.402 | G14: 20.222 | H14: 23.016
... A25: 08/15/16 04:55:00 AM | C25: 27.358 | D25: 27.444 | E25: 26.343 | F25: 27.225 | G25: 19.936 | H25: 22.489
A26: 08/15/16 05:00:00 AM | B26: 0.20833333 | C26: 27.333 | D26: 27.43 | E26: 26.329 | F26: 27.209 | G26: 19.722 | H26: 22.441
A27: 08/15/16 05:05:00 AM | C27: 27.308 | D27: 27.407 | E27: 26.268 | F27: 27.193 | G27: 19.77 | H27: 22.393
A28: 08/15/16 05:10:00 AM | C28: 27.308 | D28: 27.388 | E28: 26.204 | F28: 27.175 | G28: 19.532 | H28: 22.345
A29: 08/15/16 05:15:00 AM | C29: 27.284 | D29: 27.378 | E29: 26.158 | F29: 27.158 | G29: 19.46 | H29: 22.298
A30: 08/15/16 05:20:00 AM | C30: 27.259 | D30: 27.365 | E30: 25.91 | F30: 27.141 | G30: 19.318 | H30: 22.25
A31: 08/15/16 05:25:00 AM | C31: 27.259 | D31: 27.353 | E31: 26.007 | F31: 27.123 | G31: 19.365 | H31: 22.202
A32: 08/15/16 05:30:00 AM | C32: 27.235 | D32: 27.333 | E32: 26.048 | F32: 27.106 | G32: 19.413 | H32: 22.154
A33: 08/15/16 05:35:00 AM | C33: 27.21 | D33: 27.319 | E33: 26.027 | F33: 27.089 | G33: 19.413 | H33: 22.106
A34: 08/15/16 05:40:00 AM | C34: 27.186 | D34: 27.307 | E34: 25.729 | F34: 27.069 | G34: 19.365 | H34: 22.058
A35: 08/15/16 05:45:00 AM | C35: 27.161 | D35: 27.29 | E35: 25.989 | F35: 27.052 | G35: 19.77 | H35: 22.011
A36: 08/15/16 05:50:00 AM | C36: 27.161 | D36: 27.27 | E36: 26.186 | F36: 27.034 | G36: 19.555 | H36: 21.987
A37: 08/15/16 05:55:00 AM | C37: 27.112 | D37: 27.253 | E37: 25.803 | F37: 27.017 | G37: 19.341 | H37: 21.939
A38: 08/15/16 06:00:00 AM | C38: 27.112 | D38: 27.239 | E38: 25.924 | F38: 27.003 | G38: 19.246 | H38: 21.891
... A49: 08/15/16 06:55:00 AM | C49: 26.94 | D49: 27.077 | E49: 25.954 | F49: 26.87 | G49: 21.008 | H49: 21.748
A50: 08/15/16 07:00:00 AM | B50: 0.29166667 | C50: 26.916 | D50: 27.063 | E50: 26.12 | F50: 26.868 | G50: 21.413 | H50: 21.795
A51: 08/15/16 07:05:00 AM | C51: 26.916 | D51: 27.049 | E51: 25.875 | F51: 26.867 | G51: 21.987 | H51: 21.867
A52: 08/15/16 07:10:00 AM | C52: 26.916 | D52: 27.035 | E52: 26.062 | F52: 26.867 | G52: 22.321 | H52: 21.939
A53: 08/15/16 07:15:00 AM | C53: 26.916 | D53: 27.025 | E53: 26.038 | F53: 26.868 | G53: 22.705 | H53: 22.034
A54: 08/15/16 07:20:00 AM | C54: 26.916 | D54: 27.011 | E54: 26.43 | F54: 26.873 | G54: 23.352 | H54: 22.13
A55: 08/15/16 07:25:00 AM | C55: 26.916 | D55: 27.002 | E55: 26.659 | F55: 26.879 | G55: 24.243 | H55: 22.226
A56: 08/15/16 07:30:00 AM | C56: 26.94 | D56: 26.991 | E56: 26.775 | F56: 26.89 | G56: 24.726 | H56: 22.321
A57: 08/15/16 07:35:00 AM | C57: 26.94 | D57: 26.982 | E57: 26.861 | F57: 26.905 | G57: 25.234 | H57: 22.465
A58: 08/15/16 07:40:00 AM | C58: 26.94 | D58: 26.977 | E58: 26.969 | F58: 26.923 | G58: 25.744 | H58: 22.585
A59: 08/15/16 07:45:00 AM | C59: 26.965 | D59: 26.972 | E59: 27.018 | F59: 26.943 | G59: 26.256 | H59: 22.705
A60: 08/15/16 07:50:00 AM | C60: 26.965 | D60: 26.969 | E60: 27.12 | F60: 26.968 | G60: 26.891 | H60: 22.824
...

Sheet FIG.10-12. TDR (DATA)
A1: ALUM | B1: Tmax.amb | C1: Tmin.amb | D1: Tmax.cell | E1: ALUM+WAHE | F1: Daily swing
A2: SERIES 1 | B2: =MAX('FIG.6. ALUM (DATA)'!F2:F289) -> 39.318 | C2: =MIN('FIG.6. ALUM (DATA)'!F2:F289) -> 20.365 | D2: =MAX('FIG.6. ALUM (DATA)'!C2:C289) -> 29.59 | E2: =(B2-D2)/(B2-C2) -> 0.51326967 | F2: =B2-C2 -> 18.953
A3: SERIES 2 | B3: =MAX('FIG.6. ALUM (DATA)'!F290:F577) -> 38.087 | C3: =MIN('FIG.6. ALUM (DATA)'!F290:F577) -> 19.651 | D3: =MAX('FIG.6. ALUM (DATA)'!C290:C577) -> 28.816 | E3: =(B3-D3)/(B3-C3) -> 0.50287481 | F3: =B3-C3 -> 18.436
A4: SERIES 3 | B4: =MAX('FIG.6. ALUM (DATA)'!F578:F865) -> 38.421 | C4: =MIN('FIG.6. ALUM (DATA)'!F578:F865) -> 19.746 | D4: =MAX('FIG.6. ALUM (DATA)'!C578:C865) -> 28.791 | E4: =(B4-D4)/(B4-C4) -> 0.51566265 | F4: =B4-C4 -> 18.675
A5: SERIES 4 | B5: =MAX('FIG.6. ALUM (DATA)'!F866:F1154) -> 37.124 | C5: =MIN('FIG.6. ALUM (DATA)'!F866:F1154) -> 19.674 | D5: =MAX('FIG.6. ALUM (DATA)'!C866:C1154) -> 27.949 | E5: =(B5-D5)/(B5-C5) -> 0.52578797 | F5: =B5-C5 -> 17.45
A7: ALUM+WAHE | B7: Tmax.amb | C7: Tmin.amb | D7: Tmax.cell | E7: ALUM | F7: Daily swing
A8: SERIES 1 | B8: =MAX('FIG.7. ALUM+WAHE (DATA)'!G2:G289) -> 35.049 | C8: =MIN('FIG.7. ALUM+WAHE (DATA)'!G2:G289) -> 15.127 | D8: =MAX('FIG.7. ALUM+WAHE (DATA)'!C2:C289) -> 25.647 | E8: =(B8-D8)/(B8-C8) -> 0.47194057 | F8: =B8-C8 -> 19.922
A9: SERIES 2 | B9: =MAX('FIG.7. ALUM+WAHE (DATA)'!G290:G577) -> 35.155 | C9: =MIN('FIG.7. ALUM+WAHE (DATA)'!G290:G577) -> 14.768 | D9: =MAX('FIG.7. ALUM+WAHE (DATA)'!C290:C577) -> 25.793 | E9: =(B9-D9)/(B9-C9) -> 0.45921421 | F9: =B9-C9 -> 20.387
A10: SERIES 3 | B10: =MAX('FIG.7. ALUM+WAHE (DATA)'!G578:G865) -> 43.435 | C10: =MIN('FIG.7. ALUM+WAHE (DATA)'!G578:G865) -> 16.677 | D10: =MAX('FIG.7. ALUM+WAHE (DATA)'!C578:C865) -> 26.695 | E10: =(B10-D10)/(B10-C10) -> 0.6256073 | F10: =B10-C10 -> 26.758
A11: SERIES 4 | B11: =MAX('FIG.7. ALUM+WAHE (DATA)'!G866:G1154) -> 39.715 | C11: =MIN('FIG.7. ALUM+WAHE (DATA)'!G866:G1154) -> 17.32 | D11: =MAX('FIG.7. ALUM+WAHE (DATA)'!C866:C1154) -> 28.196 | E11: =(B11-D11)/(B11-C11) -> 0.51435588 | F11: =B11-C11 -> 22.395
A13: ALUM+WAHE+SP | B13: Tmax.amb | C13: Tmin.amb | D13: Tmax.cell | E13: ALUM+WAHE+SP | F13: Daily swing
A14: SERIES 1 | B14: =MAX('FIG.9. ALUM+WAHE+SPRAY (DATA)'!G2:G289) -> 43.768 | C14: =MIN('FIG.9. ALUM+WAHE+SPRAY (DATA)'!G2:G289) -> 17.32 | D14: =MAX('FIG.9. ALUM+WAHE+SPRAY (DATA)'!C2:C289) -> 31.153 | E14: =(B14-D14)/(B14-C14) -> 0.47697368 | F14: =B14-C14 -> 26.448
A15: SERIES 2 | B15: =MAX('FIG.9. ALUM+WAHE+SPRAY (DATA)'!G290:G577) -> 43.254 | C15: =MIN('FIG.9. ALUM+WAHE+SPRAY (DATA)'!G290:G577) -> 16.058 | D15: =MAX('FIG.9. ALUM+WAHE+SPRAY (DATA)'!C290:C577) -> 30.697 | E15: =(B15-D15)/(B15-C15) -> 0.46172231 | F15: =B15-C15 -> 27.196
A16: SERIES 3 | B16: =MAX('FIG.9. ALUM+WAHE+SPRAY (DATA)'!G578:G865) -> 39.658 | C16: =MIN('FIG.9. ALUM+WAHE+SPRAY (DATA)'!G578:G865) -> 15.223 | D16: =MAX('FIG.9. ALUM+WAHE+SPRAY (DATA)'!C578:C865) -> 30.142 | E16: =(B16-D16)/(B16-C16) -> 0.38944138 | F16: =B16-C16 -> 24.435
A17: SERIES 4 | B17: =MAX('FIG.9. ALUM+WAHE+SPRAY (DATA)'!G866:G1154) -> 39.943 | C17: =MIN('FIG.9. ALUM+WAHE+SPRAY (DATA)'!G866:G1154) -> 14.721 | D17: =MAX('FIG.9. ALUM+WAHE+SPRAY (DATA)'!C866:C1154) -> 29.815 | E17: =(B17-D17)/(B17-C17) -> 0.4015542 | F17: =B17-C17 -> 25.222
A19: INSU+WAHE | B19: Tmax.amb | C19: Tmin.amb | D19: Tmax.cell | E19: INSU+WAHE | F19: Daily swing
A20: SERIES 1 | B20: =MAX('FIG.5. INSU+WAHE (DATA)'!D2:D289) -> 36.146 | C20: =MIN('FIG.5. INSU+WAHE (DATA)'!D2:D289) -> 15.891 | D20: =MAX('FIG.5. INSU+WAHE (DATA)'!F2:F289) -> 23.738 | E20: =(B20-D20)/(B20-C20) -> 0.61258948 | F20: =B20-C20 -> 20.255
A21: SERIES 2 | B21: =MAX('FIG.5. INSU+WAHE (DATA)'!D290:D577) -> 35.315 | C21: =MIN('FIG.5. INSU+WAHE (DATA)'!D290:D577) -> 15.509 | D21: =MAX('FIG.5. INSU+WAHE (DATA)'!F290:F577) -> 22.259 | E21: =(B21-D21)/(B21-C21) -> 0.65919418 | F21: =B21-C21 -> 19.806
A22: SERIES 3 | B22: =MAX('FIG.5. INSU+WAHE (DATA)'!D578:D865) -> 37.315 | C22: =MIN('FIG.5. INSU+WAHE (DATA)'!D578:D865) -> 15.963 | D22: =MAX('FIG.5. INSU+WAHE (DATA)'!F578:F865) -> 22.659 | E22: =(B22-D22)/(B22-C22) -> 0.6863994 | F22: =B22-C22 -> 21.352
A23: SERIES 4 | B23: =MAX('FIG.5. INSU+WAHE (DATA)'!D866:D1154) -> 31.868 | C23: =MIN('FIG.5. INSU+WAHE (DATA)'!D866:D1154) -> 16.034 | D23: =MAX('FIG.5. INSU+WAHE (DATA)'!F866:F1154) -> 21.877 | E23: =(B23-D23)/(B23-C23) -> 0.63098396 | F23: =B23-C23 -> 15.834
A25: INSU | B25: Tmax.amb | C25: Tmin.amb | D25: Tmax.cell | E25: INSU | F25: Daily swing
A26: SERIES 1 | B26: =MAX('FIG.4. INSU (DATA)'!C2:C289) -> 40.631 | C26: =MIN('FIG.4. INSU (DATA)'!C2:C289) -> 18.319 | D26: =MAX('FIG.4. INSU (DATA)'!F2:F289) -> 28.608 | E26: =(B26-D26)/(B26-C26) -> 0.53885801 | F26: =B26-C26 -> 22.312
A27: SERIES 2 | B27: =MAX('FIG.4. INSU (DATA)'!C290:C577) -> 36.146 | C27: =MIN('FIG.4. INSU (DATA)'!C290:C577) -> 16.773 | D27: =MAX('FIG.4. INSU (DATA)'!F290:F577) -> 27.391 | E27: =(B27-D27)/(B27-C27) -> 0.45191762 | F27: =B27-C27 -> 19.373
A28: SERIES 3 | B28: =MAX('FIG.4. INSU (DATA)'!C578:C865) -> 34.15 | C28: =MIN('FIG.4. INSU (DATA)'!C578:C865) -> 18.604 | D28: =MAX('FIG.4. INSU (DATA)'!F578:F865) -> 26.683 | E28: =(B28-D28)/(B28-C28) -> 0.48031648 | F28: =B28-C28 -> 15.546
A29: SERIES 4 | B29: =MAX('FIG.4. INSU (DATA)'!C866:C1154) -> 32.51 | C29: =MIN('FIG.4. INSU (DATA)'!C866:C1154) -> 17.796 | D29: =MAX('FIG.4. INSU (DATA)'!F866:F1154) -> 25.022 | E29: =(B29-D29)/(B29-C29) -> 0.50890309 | F29: =B29-C29 -> 14.714
A31: CONTROL | B31: Tmax.amb | C31: Tmin.amb | D31: Tmax.cell | E31: CONTROL | F31: Daily swing
A32: SERIES 1 | B32: 35.049 | C32: 15.127 | D32: 28.05205 | E32: =(B32-D32)/(B32-C32) -> 0.35121725 | F32: =B32-C32 -> 19.922
A33: SERIES 2 | B33: 35.155 | C33: 14.768 | D33: 27.97583 | E33: =(B33-D33)/(B33-C33) -> 0.3521445 | F33: =B33-C33 -> 20.387
A34: SERIES 3 | B34: 43.435 | C34: 16.677 | D34: 29.09235 | E34: =(B34-D34)/(B34-C34) -> 0.53601353 | F34: =B34-C34 -> 26.758
A35: SERIES 4 | B35: 39.715 | C35: 17.32 | D35: 30.99373 | E35: =(B35-D35)/(B35-C35) -> 0.38942934 | F35: =B35-C35 -> 22.395
A36: SERIES 1 | B36: 36.146 | C36: 15.891 | D36: 28.642 | E36: =(B36-D36)/(B36-C36) -> 0.37047643 | F36: =B36-C36 -> 20.255
A37: SERIES 2 | B37: 35.315 | C37: 15.509 | D37: 28.048 | E37: =(B37-D37)/(B37-C37) -> 0.36690902 | F37: =B37-C37 -> 19.806
A38: SERIES 3 | B38: 37.315 | C38: 15.963 | D38: 28.667 | E38: =(B38-D38)/(B38-C38) -> 0.40502061 | F38: =B38-C38 -> 21.352
A39: SERIES 4 | B39: 31.868 | C39: 16.034 | D39: 26.842 | E39: =(B39-D39)/(B39-C39) -> 0.31741821 | F39: =B39-C39 -> 15.834

Sheet FIG.14. PIPE LENGTH (DATA)
A1: Air velocity | B1: Pipe diameter | C1: Pipe length (m)
A2: (m/s) | B2: (m) | C2: (m)
C3: 5 | D3: 10 | E3: 15 | F3: 20 | G3: 25 | H3: 30 | I3: 35 | J3: 40 | K3: 45 | L3: 50
A4: 1 m/s | B4: .1 | C4: 28.42319 | D4: 45.257768 | E4: 52.340754 | F4: 54.884491 | G4: 55.745018 | H4: 56.030184 | I4: 56.124036 | J4: 56.154854 | K4: 56.164966 | L4: 56.168283
B5: .15 | C5: 41.673102 | D5: 75.17285 | E5: 97.68665 | F5: 111.05513 | G5: 118.41701 | H5: 122.3036 | I5: 124.30982 | J5: 125.33338 | K5: 125.85249 | L5: 126.11496
B6: .2 | C6: 53.42172 | D6: 101.12638 | E6: 139.60763 | F6: 168.18204 | G6: 188.12191 | H6: 201.44062 | I6: 210.07868 | J6: 215.57453 | K6: 219.02861 | L6: 221.18277
B7: .25 | C7: 64.360235 | D7: 124.53486 | E7: 177.3606 | F7: 221.23036 | G7: 256.01336 | H7: 282.59258 | I7: 302.33579 | J7: 316.69479 | K7: 326.97833 | L7: 334.26218
B8: .3 | C8: 74.743346 | D8: 146.2888 | E8: 211.9633 | F8: 269.97044 | G8: 319.48767 | H8: 360.54187 | I8: 393.76384 | J8: 420.1241 | K8: 440.71527 | L8: 456.60431
A10: 2 m/s | B10: .1 | C10: 48.976308 | D10: 82.308548 | E10: 99.501859 | F10: 107.11593 | G10: 110.25853 | H10: 111.51768 | I10: 112.01616 | J10: 112.21257 | K10: 112.28981 | L10: 112.32016
B11: .15 | C11: 70.641357 | D11: 131.04712 | E11: 176.16326 | F11: 206.56927 | G11: 225.6684 | H11: 237.13974 | I11: 243.84514 | J11: 247.70265 | K11: 249.90147 | L11: 251.14824
B12: .2 | C12: 90.053148 | D12: 173.15223 | E12: 244.33723 | F12: 301.53278 | G12: 345.16886 | H12: 377.16269 | I12: 399.94318 | J12: 415.82726 | K12: 426.74159 | L12: 434.1658
B13: .25 | C13: 108.20026 | D13: 211.38063 | E13: 305.41148 | F13: 387.62802 | G13: 456.95183 | H13: 513.63773 | I13: 558.83757 | J13: 594.16082 | K13: 621.33402 | L13: 641.98529
B14: .3 | C14: 125.47347 | D14: 247.14071 | E14: 361.64372 | F14: 466.41333 | G14: 559.83652 | H14: 641.24585 | I14: 710.77497 | J14: 769.14569 | K14: 817.44585 | L14: 856.93731
A16: 3 m/s | B16: .1 | C16: 66.46687 | D16: 115.03614 | E16: 142.99783 | F16: 156.93503 | G16: 163.38359 | H16: 166.26428 | I16: 167.5309 | J16: 168.08394 | K16: 168.32468 | L16: 168.42933
B17: .15 | C17: 95.049574 | D17: 178.85841 | E17: 244.94083 | F17: 292.60184 | G17: 324.81051 | H17: 345.63045 | I17: 358.70451 | J17: 366.76577 | K17: 371.68031 | L17: 374.65582
B18: .2 | C18: 120.83194 | D18: 234.13953 | E18: 334.16278 | F18: 417.85838 | G18: 484.81196 | H18: 536.47163 | I18: 575.23052 | J18: 603.70377 | K18: 624.29868 | L18: 639.02839
B19: .25 | C19: 144.98072 | D19: 284.56885 | E19: 414.14532 | F19: 530.41375 | G19: 631.60585 | H19: 717.36414 | I19: 788.41889 | J19: 846.19711 | K19: 892.46715 | L19: 929.06991
B20: .3 | C20: 168.0075 | D20: 331.94135 | E20: 488.11363 | F20: 633.53282 | G20: 766.08824 | H20: 884.59442 | I20: 988.71539 | J20: 1078.8099 | K20: 1155.7423 | L20: 1220.6963
A22: 4 m/s | B22: .1 | C22: 84.884019 | D22: 148.56316 | E22: 186.78614 | F22: 206.73758 | G22: 216.39579 | H22: 220.90052 | I22: 222.96511 | J22: 223.90374 | K22: 224.3289 | L22: 224.52117
B23: .15 | C23: 121.00593 | D23: 228.89708 | E23: 315.68829 | F23: 379.90706 | G23: 424.5444 | H23: 454.2395 | I23: 473.42202 | J23: 485.57933 | K23: 493.1913 | L23: 497.92118
B24: .2 | C24: 153.64246 | D24: 298.55912 | E24: 427.89989 | F24: 537.76974 | G24: 627.24709 | H24: 697.64821 | I24: 751.55283 | J24: 791.97257 | K24: 821.80821 | L24: 843.57672
B25: .25 | C25: 184.2337 | D25: 362.23238 | E25: 528.57742 | F25: 679.26594 | G25: 811.9695 | H25: 925.95859 | I25: 1021.7954 | J25: 1100.9286 | K25: 1165.301 | L25: 1217.0328
B26: .3 | C26: 213.40101 | D26: 422.10095 | E26: 621.80406 | F26: 808.95315 | G26: 980.93991 | H26: 1136.1746 | I26: 1274.0301 | J26: 1394.6961 | K26: 1498.9878 | L26: 1588.1457
A28: 5 m/s | B28: .1 | C28: 101.44573 | D28: 179.47487 | E28: 228.23693 | F28: 254.86788 | G28: 268.34999 | H28: 274.91362 | I28: 278.0482 | J28: 279.53142 | K28: 280.23019 | L28: 280.5587
B29: .15 | C29: 144.18098 | D29: 274.09271 | E29: 380.60602 | F29: 461.38092 | G29: 519.08609 | H29: 558.57446 | I29: 584.80767 | J29: 601.89366 | K29: 612.87898 | L29: 619.88329
B30: .2 | C30: 182.86646 | D30: 356.29216 | E30: 512.6902 | F30: 647.45796 | G30: 759.10774 | H30: 848.62977 | I30: 918.54628 | J30: 972.0376 | K30: 1012.321 | L30: 1042.2982
B31: .25 | C31: 219.1493 | D31: 431.57153 | E31: 631.34102 | F31: 813.94016 | G31: 976.55394 | H31: 1118.0449 | I31: 1238.69 | J31: 1339.7978 | K31: 1423.312 | L31: 1491.4715
B32: .3 | C32: 253.75104 | D32: 502.43839 | E32: 741.39468 | F32: 966.68092 | G32: 1175.3077 | H32: 1365.3259 | I32: 1535.796 | J32: 1686.6654 | K32: 1818.5906 | L32: 1932.742
